Workbook

Sheet Liste usagers 2025
K1: Gestion et temporalité | P1: Origine et nature de la demande | T1: Traitement apporté
A2: N° de dossier | B2: Nom | C2: Prénom | D2: Genre | E2: Tranche d'âge | F2: Adresse | G2: N° | H2: Secteur | I2: N°de téléphone | J2: Adresse mail | K2: Titulaire | L2: Date de reception | M2: Date d'ouverture | N2: Delai de traitement | O2: Date de clôture | P2: Type de conflit | Q2: Autre type de conflit | R2: Envoyeur | S2: Autres | T2: Partenaire | U2: Autres | V2: Type de médiation | W2: Orientation | X2: Autres | Y2: Statut | Z2: Issue
A3: 1 | B3: Wester | C3: Théo | D3: Homme | E3: 30 - 50 ans | F3: Avenue Docteur Zamenhof | G3: 2/164 | H3: =IFERROR(VLOOKUP(F3, Index!C:D, 2, FALSE), "") -> Vaillance | I3: 0476/893403 | J3: theo.wester@gmail.com | K3: Louise | L3: 45663 | M3: 45663 | N3: =IF(OR(L3="", M3=""), "", IF(L3=M3, 1, M3 - L3)) -> 1 | O3: 45665 | P3: Conflits Locatifs | R3: Demande spontanée | T3: Autre | U3: PILDA | V3: Individuelle | W3: Autre | X3: PILDA | Y3: Clôturé | Z3: Réorientation
A4: 2 | B4: Grami | C4: Wannes | D4: Homme | E4: 30 - 50 ans | F4: Chaussée de Ninove 623-739 /700-788 | G4: 707 | H4: =IFERROR(VLOOKUP(F4, Index!C:D, 2, FALSE), "") -> Peterbos | I4: 0486/939870 | K4: Pascal | L4: 45666 | M4: 45671 | N4: =IF(OR(L4="", M4=""), "", IF(L4=M4, 1, M4 - L4)) -> 5 | O4: 45770 | P4: Copropriété | R4: ULAC | V4: Individuelle | Y4: Clôturé | Z4: Apaisement
A5: 3 | B5: Gambier | C5: Manon | D5: Femme | E5: 18 - 30 ans | F5: Rue Georges Moreau | G5: 190 | H5: =IFERROR(VLOOKUP(F5, Index!C:D, 2, FALSE), "") -> Cureghem | I5: 33663775606 | J5: manongambier95@gmail.com | K5: Pascal | L5: 45664 | M5: 45666 | N5: =IF(OR(L5="", M5=""), "", IF(L5=M5, 1, M5 - L5)) -> 2 | O5: 45692 | P5: Conflits de voisinage | Q5: nuisances sonores | R5: Déjà venu | T5: Autre | U5: Ecole St Pierre | V5: Individuelle | Y5: Clôturé | Z5: Refus (de l'une partie ou des deux)
A6: 4 | B6: Sibide | C6: Fatoumata | D6: Femme | H6: =IFERROR(VLOOKUP(F6, Index!C:D, 2, FALSE), "") | J6: diakiteadma113@gmail.com | K6: Pascal | L6: 45646 | M6: 45659 | N6: =IF(OR(L6="", M6=""), "", IF(L6=M6, 1, M6 - L6)) -> 13 | P6: Conflits Locatifs | R6: Demande spontanée | V6: Individuelle | Y6: Clôturé | Z6: Impossibilité technique (non-joignables)
A7: 5 | B7: Rouyer | C7: Emma | D7: Femme | E7: 30 - 50 ans | H7: =IFERROR(VLOOKUP(F7, Index!C:D, 2, FALSE), "") | I7: 0485/398629 | J7: emma_zebr@yahoo.fr | K7: Pascal | L7: 45644 | M7: 45666 | N7: =IF(OR(L7="", M7=""), "", IF(L7=M7, 1, M7 - L7)) -> 22 | O7: 45749 | P7: Autres conflits | Q7: Entre artistes (propriété intellectuelle) | R7: Déjà venu | T7: TSR | V7: Individuelle | W7: Autre | X7: Avocat | Y7: Clôturé | Z7: Refus (de l'une partie ou des deux)
A8: 6 | B8: Van Saene | C8: David | D8: Homme | E8: 30 - 50 ans | F8: Avenue Eugène Ysaÿe | G8: 105 | H8: =IFERROR(VLOOKUP(F8, Index!C:D, 2, FALSE), "") -> Parc | I8: 0486/510427 | K8: Pascal | L8: 45639 | M8: 45660 | N8: =IF(OR(L8="", M8=""), "", IF(L8=M8, 1, M8 - L8)) -> 21 | O8: 45666 | P8: Conflits de voisinage | Q8: nuisances sonores | R8: Déjà venu | V8: Individuelle | Y8: Clôturé | Z8: Apaisement
A9: 7 | B9: Benayad | C9: Abdellatif | D9: Homme | F9: Rue de Douvres | G9: 26 | H9: =IFERROR(VLOOKUP(F9, Index!C:D, 2, FALSE), "") -> Vaillance | I9: 0495777585 | J9: renovaben@yahoo.fr | K9: Pascal | L9: 45642 | M9: 45665 | N9: =IF(OR(L9="", M9=""), "", IF(L9=M9, 1, M9 - L9)) -> 23 | P9: Conflits de voisinage | R9: Demande spontanée | V9: Individuelle | Y9: Clôturé | Z9: Impossibilité technique (non-joignables)
A10: 8 | B10: Carvalho | C10: Daniel | D10: Homme | E10: 30 - 50 ans | F10: ADRESSE | H10: =IFERROR(VLOOKUP(F10, Index!C:D, 2, FALSE), "") -> SECTEUR | I10: 0494831519 | J10: dani.vdc@live.com | K10: Sedia | L10: 45664 | M10: 45664 | N10: =IF(OR(L10="", M10=""), "", IF(L10=M10, 1, M10 - L10)) -> 1 | O10: 45665 | P10: Conflits de voisinage | R10: Demande spontanée | V10: Individuelle | Y10: Clôturé | Z10: Refus (de l'une partie ou des deux)
A11: 9 | D11: Femme | E11: 50 ans et + | F11: Rue Buffon | H11: =IFERROR(VLOOKUP(F11, Index!C:D, 2, FALSE), "") -> Peterbos | K11: Louise | L11: 45663 | M11: 45663 | N11: =IF(OR(L11="", M11=""), "", IF(L11=M11, 1, M11 - L11)) -> 1 | O11: 45713 | P11: Conflits de voisinage | Q11: arbre | R11: Demande spontanée | V11: Individuelle | Y11: Clôturé | Z11: Impossibilité technique (non-joignables)
A12: 10 | D12: Homme | E12: 30 - 50 ans | F12: Square de l'Aviation | G12: 28 | H12: =IFERROR(VLOOKUP(F12, Index!C:D, 2, FALSE), "") -> Cureghem | K12: Louise | L12: 45664 | M12: 45664 | N12: =IF(OR(L12="", M12=""), "", IF(L12=M12, 1, M12 - L12)) -> 1 | O12: 45713 | P12: Conflits de voisinage | Q12: nuisances sonores | R12: Demande spontanée | V12: Individuelle | Y12: Clôturé | Z12: Impossibilité technique (non-joignables)
A13: 11 | B13: Adakaev | D13: Homme | F13: ADRESSE | H13: =IFERROR(VLOOKUP(F13, Index!C:D, 2, FALSE), "") -> SECTEUR | J13: adakaev@outlook.com | K13: Louise | L13: 45664 | M13: 45664 | N13: =IF(OR(L13="", M13=""), "", IF(L13=M13, 1, M13 - L13)) -> 1 | O13: 45664 | P13: Autres conflits | Q13: stationnement | R13: Demande spontanée | V13: Individuelle | W13: Autre | X13: SAC | Y13: Clôturé | Z13: Réorientation
A14: 12 | B14: Cesatti | C14: Nellio | D14: Homme | E14: 30 - 50 ans | F14: Place Henri De Smet | G14: 1 | H14: =IFERROR(VLOOKUP(F14, Index!C:D, 2, FALSE), "") -> Scheut | I14: 0474/76 57 80 | K14: Louise | L14: 45666 | M14: 45671 | N14: =IF(OR(L14="", M14=""), "", IF(L14=M14, 1, M14 - L14)) -> 5 | O14: 45939 | P14: Conflits de voisinage | R14: Demande spontanée | V14: Individuelle | W14: TSR | X14: Amine | Y14: Clôturé | Z14: Réorientation
A15: 13 | B15: Bulambo | C15: Dunia | D15: Homme | E15: 30 - 50 ans | F15: Rue de l'Orphelinat | G15: 33 | H15: =IFERROR(VLOOKUP(F15, Index!C:D, 2, FALSE), "") -> Scheut | I15: 0493/46 24 12 | K15: Pascal | L15: 45673 | M15: 45673 | N15: =IF(OR(L15="", M15=""), "", IF(L15=M15, 1, M15 - L15)) -> 1 | O15: 45761 | P15: Conflits de voisinage | R15: Déjà venu | T15: Police | V15: Individuelle | Y15: Clôturé | Z15: Interruption du processus de médiation
A16: 14 | B16: antagana | C16: sandrine | D16: Femme | E16: 30 - 50 ans | F16: ADRESSE | H16: =IFERROR(VLOOKUP(F16, Index!C:D, 2, FALSE), "") -> SECTEUR | I16: 0465275893 | J16: tang.ana@outlook.com | K16: Sedia | L16: 45665 | M16: 45665 | N16: =IF(OR(L16="", M16=""), "", IF(L16=M16, 1, M16 - L16)) -> 1 | O16: 45665 | P16: Conflits Locatifs | Q16: état des lieux | R16: Demande spontanée | V16: Individuelle | Y16: Clôturé | Z16: Refus (de l'une partie ou des deux)
A17: 15 | B17: Cenem | C17: Alexandre | D17: Homme | E17: 30 - 50 ans | F17: ADRESSE | H17: =IFERROR(VLOOKUP(F17, Index!C:D, 2, FALSE), "") -> SECTEUR | I17: 0478357132 | K17: Sedia | L17: 45664 | M17: 45672 | N17: =IF(OR(L17="", M17=""), "", IF(L17=M17, 1, M17 - L17)) -> 8 | O17: 45672 | P17: Conflits Familiaux/ Conjugaux | Q17: separation garde de l enfant | R17: Demande spontanée | V17: Individuelle | Y17: Clôturé | Z17: Réorientation
A18: 16 | B18: lawniczak | C18: marlon | D18: Femme | F18: ADRESSE | H18: =IFERROR(VLOOKUP(F18, Index!C:D, 2, FALSE), "") -> SECTEUR | I18: 0456752606 | K18: Sedia | L18: 45660 | M18: 45660 | N18: =IF(OR(L18="", M18=""), "", IF(L18=M18, 1, M18 - L18)) -> 1 | O18: 45965 | P18: Conflits Familiaux/ Conjugaux | Q18: garde enfant | R18: Demande spontanée | V18: Individuelle | Y18: Clôturé | Z18: Refus (de l'une partie ou des deux)
A19: 17 | B19: Almi | C19: El hassan | D19: Homme | E19: 30 - 50 ans | F19: ADRESSE | H19: =IFERROR(VLOOKUP(F19, Index!C:D, 2, FALSE), "") -> SECTEUR | I19: 0486087344 | J19: slaama@abcoop.be | K19: Sedia | L19: 45673 | M19: 45673 | N19: =IF(OR(L19="", M19=""), "", IF(L19=M19, 1, M19 - L19)) -> 1 | P19: Conflits de voisinage | R19: Demande spontanée | V19: Individuelle | Y19: Clôturé
A20: 18 | B20: Benatia | C20: mohamed | D20: Homme | E20: 50 ans et + | F20: ADRESSE | H20: =IFERROR(VLOOKUP(F20, Index!C:D, 2, FALSE), "") -> SECTEUR | I20: 0487447501 | K20: Sedia | L20: 45665 | M20: 45665 | N20: =IF(OR(L20="", M20=""), "", IF(L20=M20, 1, M20 - L20)) -> 1 | O20: 45665 | P20: Autres conflits | Q20: conflit avec infor sourd | R20: Demande spontanée | V20: Individuelle | Y20: Clôturé | Z20: Réorientation
A21: 19 | D21: Femme | E21: 50 ans et + | F21: Avenue de la Libre Académie | G21: 72 | H21: =IFERROR(VLOOKUP(F21, Index!C:D, 2, FALSE), "") -> Parc | K21: Louise | L21: 45685 | M21: 45685 | N21: =IF(OR(L21="", M21=""), "", IF(L21=M21, 1, M21 - L21)) -> 1 | O21: 45685 | P21: Conflits Locatifs | R21: Justice de Paix | S21: permanence | V21: Individuelle | Y21: Clôturé | Z21: Accord écrit
A22: 20 | D22: Femme | E22: 50 ans et + | F22: ADRESSE | H22: =IFERROR(VLOOKUP(F22, Index!C:D, 2, FALSE), "") -> SECTEUR | K22: Louise | L22: 45685 | M22: 45685 | N22: =IF(OR(L22="", M22=""), "", IF(L22=M22, 1, M22 - L22)) -> 1 | O22: 45685 | P22: Conflits Locatifs | R22: Justice de Paix | S22: permanence | V22: Individuelle | W22: Justice de Paix | Y22: Clôturé | Z22: Réorientation
A23: 21 | B23: Nasir | C23: Warsan | D23: Femme | E23: 30 - 50 ans | F23: Rue des Goujons | G23: 59 | H23: =IFERROR(VLOOKUP(F23, Index!C:D, 2, FALSE), "") -> Cureghem | I23: 0465/662462 | K23: Louise | L23: 45694 | M23: 45694 | N23: =IF(OR(L23="", M23=""), "", IF(L23=M23, 1, M23 - L23)) -> 1 | O23: 45715 | P23: Conflits de voisinage | R23: Demande spontanée | V23: Individuelle | Y23: Clôturé | Z23: Impossibilité technique (non-joignables)
A24: 22 | B24: Genkhang | C24: Rigzin | D24: Femme | E24: 50 ans et + | F24: Avenue du Roi Soldat | G24: 11 | H24: =IFERROR(VLOOKUP(F24, Index!C:D, 2, FALSE), "") -> Parc | I24: 0474995189 | J24: himalayancraft4you@gmail.com | K24: Sedia | L24: 45693 | M24: 45694 | N24: =IF(OR(L24="", M24=""), "", IF(L24=M24, 1, M24 - L24)) -> 1 | P24: Conflits de voisinage | Q24: nuisances sonores | R24: Demande spontanée | V24: Individuelle | Y24: Clôturé | Z24: Apaisement
A25: 23 | B25: Kenf | C25: Benedicte | D25: Femme | E25: 30 - 50 ans | F25: Avenue d'Itterbeek | G25: 121 | H25: =IFERROR(VLOOKUP(F25, Index!C:D, 2, FALSE), "") -> Neerpede | K25: Louise | L25: 45693 | M25: 45694 | N25: =IF(OR(L25="", M25=""), "", IF(L25=M25, 1, M25 - L25)) -> 1 | O25: 45876 | P25: Cohabitation/colocation | R25: Demande spontanée | V25: Individuelle | W25: Justice de Paix | Y25: Clôturé | Z25: Réorientation
A26: 24 | B26: Amyay | C26: Abdelaziz | D26: Homme | E26: 50 ans et + | F26: Rue Victor Rauter | G26: 185 | H26: =IFERROR(VLOOKUP(F26, Index!C:D, 2, FALSE), "") -> Vaillance | I26: 0487/531305 | K26: Louise | L26: 45694 | M26: 45694 | N26: =IF(OR(L26="", M26=""), "", IF(L26=M26, 1, M26 - L26)) -> 1 | O26: 45876 | P26: Conflits de voisinage | R26: Demande spontanée | V26: Individuelle | Y26: Clôturé | Z26: Refus (de l'une partie ou des deux)
A27: 25 | B27: Sanciaume | C27: Luc | D27: Homme | E27: 30 - 50 ans | F27: Rue de Veeweyde | G27: 29 | H27: =IFERROR(VLOOKUP(F27, Index!C:D, 2, FALSE), "") -> Vaillance | I27: 0471/36 58 15 | K27: Louise | L27: 45698 | M27: 45698 | N27: =IF(OR(L27="", M27=""), "", IF(L27=M27, 1, M27 - L27)) -> 1 | O27: 45876 | P27: Conflits de voisinage | R27: Demande spontanée | V27: Individuelle | Y27: Clôturé | Z27: Impossibilité technique (non-joignables)
A28: 26 | B28: D'Ostunx | C28: cathy | D28: Femme | E28: 30 - 50 ans | H28: =IFERROR(VLOOKUP(F28, Index!C:D, 2, FALSE), "") | I28: 0495498855 | K28: Sedia | L28: 45706 | M28: 45706 | N28: =IF(OR(L28="", M28=""), "", IF(L28=M28, 1, M28 - L28)) -> 1 | O28: 45874 | P28: Conflits Familiaux/ Conjugaux | R28: Demande spontanée | V28: Individuelle | W28: Justice de Paix | Y28: Clôturé | Z28: Apaisement avant médiation
A29: 27 | B29: Fourneau | C29: olivier | D29: Homme | E29: 30 - 50 ans | F29: Rue Adolphe Willemyns | G29: 46 | H29: =IFERROR(VLOOKUP(F29, Index!C:D, 2, FALSE), "") -> Peterbos | I29: 0485794472 | K29: Pascal | L29: 45706 | M29: 45706 | N29: =IF(OR(L29="", M29=""), "", IF(L29=M29, 1, M29 - L29)) -> 1 | O29: 45758 | P29: Conflits de voisinage | Q29: mur mitoyen | R29: Justice de Paix | V29: Individuelle | Y29: Clôturé | Z29: Interruption du processus de médiation
A30: 28 | B30: Vanbroeck | C30: gretta | D30: Femme | E30: 30 - 50 ans | F30: Avenue Marius Renard | G30: 47 | H30: =IFERROR(VLOOKUP(F30, Index!C:D, 2, FALSE), "") -> Parc | I30: 0478637118 | K30: Sedia | L30: 45707 | M30: 45707 | N30: =IF(OR(L30="", M30=""), "", IF(L30=M30, 1, M30 - L30)) -> 1 | P30: Conflits de voisinage | Q30: nuisance sonore | R30: Justice de Paix | V30: Individuelle | Y30: Clôturé | Z30: Réorientation
A31: 29 | D31: Femme | E31: 50 ans et + | F31: Avenue Romain Rolland | G31: 87 | H31: =IFERROR(VLOOKUP(F31, Index!C:D, 2, FALSE), "") -> Parc | I31: 02/520 05 04 | K31: Louise | L31: 45698 | M31: 45713 | N31: 15 | O31: 45713 | P31: Autres conflits | Q31: proximus | R31: Demande spontanée | V31: Individuelle | Y31: Clôturé | Z31: Réorientation
A32: 30 | B32: Ouantis | C32: Ben Abdallah | D32: Homme | E32: 50 ans et + | F32: Clos des Asters | G32: 8A | H32: =IFERROR(VLOOKUP(F32, Index!C:D, 2, FALSE), "") -> La Roue | I32: 0489/85 34 95 | K32: Louise | L32: 45705 | M32: 45713 | N32: =IF(OR(L32="", M32=""), "", IF(L32=M32, 1, M32 - L32)) -> 8 | O32: 45939 | P32: Conflits de voisinage | R32: Autre | V32: Individuelle | Y32: Clôturé | Z32: Refus (de l'une partie ou des deux)
A33: 31 | B33: Waerzeggers | C33: Louis | D33: Homme | E33: 50 ans et + | F33: Avenue du Roi Soldat | G33: 34 | H33: =IFERROR(VLOOKUP(F33, Index!C:D, 2, FALSE), "") -> Parc | I33: 0474/61 61 26 | K33: Louise | L33: 45707 | M33: 45713 | N33: =IF(OR(L33="", M33=""), "", IF(L33=M33, 1, M33 - L33)) -> 6 | O33: 45713 | P33: Conflits de voisinage | Q33: arbre | R33: Autre | S33: espaces verts - commune | V33: Individuelle | Y33: Clôturé | Z33: Refus (de l'une partie ou des deux)
A34: 32 | B34: Kapp | C34: sebastien | D34: Homme | E34: 30 - 50 ans | F34: ADRESSE | H34: =IFERROR(VLOOKUP(F34, Index!C:D, 2, FALSE), "") -> SECTEUR | I34: 0487798816 | J34: seb_kapp@hotmail.com | K34: Sedia | L34: 45714 | M34: 45714 | N34: =IF(OR(L34="", M34=""), "", IF(L34=M34, 1, M34 - L34)) -> 1 | O34: 45902 | P34: Conflits Familiaux/ Conjugaux | Q34: divorce | R34: Demande spontanée | V34: Individuelle | Y34: Clôturé | Z34: Accord écrit
A35: 33 | B35: Neumans | C35: j-p | D35: Homme | E35: 50 ans et + | F35: ADRESSE | H35: =IFERROR(VLOOKUP(F35, Index!C:D, 2, FALSE), "") -> SECTEUR | I35: 0499939875 | K35: Sedia | L35: 45720 | M35: 45720 | N35: =IF(OR(L35="", M35=""), "", IF(L35=M35, 1, M35 - L35)) -> 1 | P35: Conflits Locatifs | Q35: garantie locative | R35: Demande spontanée | V35: Individuelle | Y35: Clôturé | Z35: Réorientation
A36: 34 | B36: Boly | C36: A | D36: Femme | E36: 30 - 50 ans | F36: Rue de Birmingham | G36: 300 | H36: =IFERROR(VLOOKUP(F36, Index!C:D, 2, FALSE), "") -> Scheut | I36: 0487646500 | J36: adiaratouboly@yahoo.fr | K36: Sedia | L36: 45720 | M36: 45720 | N36: =IF(OR(L36="", M36=""), "", IF(L36=M36, 1, M36 - L36)) -> 1 | P36: Conflits de voisinage | Q36: bruit enfant | R36: Demande spontanée | V36: Individuelle | Y36: Clôturé
A37: 35 | B37: Khabouchi | C37: Marwa | D37: Femme | E37: 30 - 50 ans | F37: Chaussée de Ninove 623-739 /700-788 | G37: 626 | H37: =IFERROR(VLOOKUP(F37, Index!C:D, 2, FALSE), "") -> Peterbos | I37: 0495/56 28 39 | K37: Louise | L37: 45708 | M37: 45713 | N37: =IF(OR(L37="", M37=""), "", IF(L37=M37, 1, M37 - L37)) -> 5 | O37: 45876 | P37: Conflits de voisinage | R37: Autre | S37: ASBL Après tout | V37: Individuelle | Y37: Clôturé | Z37: Refus (de l'une partie ou des deux)
A38: 36 | B38: sans nom | C38: propriétaire | D38: Femme | H38: =IFERROR(VLOOKUP(F38, Index!C:D, 2, FALSE), "") | I38: 0474472178 | K38: Sedia | L38: 45715 | M38: 45727 | N38: =IF(OR(L38="", M38=""), "", IF(L38=M38, 1, M38 - L38)) -> 12 | O38: 45965 | P38: Conflits de voisinage | R38: Demande spontanée | V38: Individuelle | Y38: Clôturé | Z38: Impossibilité technique (non-joignables)
A39: 37 | B39: sene | C39: elhadji | E39: 30 - 50 ans | F39: Rue des Goujons | H39: =IFERROR(VLOOKUP(F39, Index!C:D, 2, FALSE), "") -> Cureghem | I39: 0484161556 | K39: Sedia | L39: 45721 | M39: 45727 | N39: =IF(OR(L39="", M39=""), "", IF(L39=M39, 1, M39 - L39)) -> 6 | O39: 45965 | P39: Conflits de voisinage | Q39: bruit enfants | R39: Demande spontanée | V39: Individuelle | Y39: Clôturé | Z39: Interruption du processus de médiation
A40: 38 | B40: ercovier | C40: henri | D40: Homme | E40: 50 ans et + | F40: Avenue Tolstoï | G40: 3 | H40: =IFERROR(VLOOKUP(F40, Index!C:D, 2, FALSE), "") -> Peterbos | I40: 0496794180 | K40: Sedia | L40: 45728 | M40: 45728 | N40: =IF(OR(L40="", M40=""), "", IF(L40=M40, 1, M40 - L40)) -> 1 | O40: 45965 | P40: Conflits Familiaux/ Conjugaux | Q40: femme , enfants,amant | R40: Foyer Anderlechtois | V40: Individuelle | Y40: Clôturé | Z40: Interruption du processus de médiation
...

Sheet Synthèse 2025
E2: Synthèse des données statistiques 2025
D6: Nombre de dossiers traités | E6: =COUNT('Liste usagers 2025'!A3:A368) -> 170 | H6: Origine de la demande | J6: Pourcentage | L6: Statut des dossiers | N6: Pourcentage
H7: Collègues Prévention | I7: {=SUM(COUNTIFS('Liste usagers 2025'!R$3:R$834, {"TSR";"CRIPA";"Gardiens de la Paix";"Pôle Assuétudes";"Pôle Jeunesse";"Prévention Vol";"Technoprévention"}))} -> 3 | J7: =I7/$E$6 -> 0.017647059 | L7: En cours | M7: =COUNTIF('Liste usagers 2025'!Y$3:Y834,"En cours") -> 20 | N7: =M7/$E$6 -> 0.11764706
D8: Nombre de dossiers par type de médiation | F8: Pourcentage | H8: Services "Logement" | I8: {=SUM(COUNTIFS('Liste usagers 2025'!R$3:R$834, {"ULAC";"Syndicat des Locataires";"Foyer Anderlechtois";"Comensia"}))} -> 5 | J8: =I8/$E$6 -> 0.029411765 | L8: En attente | M8: =COUNTIF('Liste usagers 2025'!Y$3:Y834,"En attente") -> 3 | N8: =M8/$E$6 -> 0.017647059
D9: Médiation individuelle | E9: =COUNTIF('Liste usagers 2025'!V3:V368, "Individuelle") -> 153 | F9: =IF($E$11=0, 0, E9/$E$11) -> 0.94444444 | H9: Services Judiciaires | I9: {=SUM(COUNTIFS('Liste usagers 2025'!R$3:R$834, {"Justice de Paix";"Police";"Foyer Anderlechtois";"Service de Médiation à la Police"}))} -> 16 | J9: =I9/$E$6 -> 0.094117647 | L9: Clôturé | M9: =COUNTIF('Liste usagers 2025'!Y$3:Y834,"Clôturé") -> 146 | N9: =M9/$E$6 -> 0.85882353
D10: Médiation collective | E10: =COUNTIF('Liste usagers 2025'!V3:V368, "Collective") -> 9 | F10: =IF($E$11=0, 0, E10/$E$11) -> 0.055555556 | H10: Services communaux | I10: {=SUM(COUNTIFS('Liste usagers 2025'!R$3:R$834, {"CPAS";"Service Séniors";"Espaces Verts";"Service Mobilité";"Services de Médiation (autres communes)";"Antenne LISA (Vaillance)";"Antenne LISA (Peterbos)"}))} -> 1 | J10: =I10/$E$6 -> 0.0058823529 | L10: Total | M10: =SUM(M7:M9) -> 169 | N10: =SUM(N7:N9) -> 0.99411765
D11: Total | E11: =SUM(E9:E10) -> 162 | F11: =SUM(F9:F10) -> 1 | H11: Service du secteur associatif | I11: {=SUM(COUNTIFS('Liste usagers 2025'!R$3:R$834, {"PCS Albert";"Cactus";"Service Social de Cureghem";"CAW Westland";"Maison Médicale Horizon";"Maison Médicale Medikuregem"}))} -> 3 | J11: =I11/$E$6 -> 0.017647059
D12: Nombre de dossiers par secteur | F12: Pourcentage | H12: Demande spontanée | I12: =COUNTIF('Liste usagers 2025'!R$3:R834,"Demande spontanée") -> 83 | J12: =I12/$E$6 -> 0.48823529
D13: Cureghem | E13: =COUNTIF('Liste usagers 2025'!$H$3:H871,"Cureghem") -> 28 | F13: =E13/$E$21 -> 0.25925926 | H13: Autres | I13: =COUNTIF('Liste usagers 2025'!R$3:R834,"Autres") -> 0 | J13: =I13/$E$6 -> 0 | L13: Identification | N13: Pourcentage
D14: Industrie | E14: =COUNTIF('Liste usagers 2025'!$H$3:H873,"Industrie") -> 0 | F14: =E14/$E$21 -> 0 | H14: Total | I14: =SUM(I7:I13) -> 111 | J14: =SUM(J7:J13) -> 0.65294118 | L14: Genre
D15: Vaillance | E15: =COUNTIF('Liste usagers 2025'!$H$3:H874,"Vaillance") -> 23 | F15: =E15/$E$21 -> 0.21296296 | L15: Homme | M15: =COUNTIF('Liste usagers 2025'!$D$3:D834,"Homme") -> 69 | N15: =M15/$M$18 -> 0.42857143
D16: Scheut | E16: =COUNTIF('Liste usagers 2025'!$H$3:H875,"Scheut") -> 21 | F16: =E16/$E$21 -> 0.19444444 | H16: Traitement apporté | J16: Pourcentage | L16: Femme | M16: =COUNTIF('Liste usagers 2025'!$D$3:D835,"Femme") -> 92 | N16: =M16/$M$18 -> 0.57142857
D17: Parc | E17: =COUNTIF('Liste usagers 2025'!$H$3:H876,"Parc") -> 14 | F17: =E17/$E$21 -> 0.12962963 | H17: Partenariats/collaborations | L17: X | M17: =COUNTIF('Liste usagers 2025'!$D$3:D836,"X") -> 0 | N17: =M17/$M$18 -> 0
D18: Peterbos | E18: =COUNTIF('Liste usagers 2025'!$H$3:H877,"Peterbos") -> 11 | F18: =E18/$E$21 -> 0.10185185 | H18: Collègues Prévention | I18: {=SUM(COUNTIFS('Liste usagers 2025'!T$3:T$834, {"TSR";"CRIPA";"Gardiens de la Paix";"Pôle Assuétudes";"Pôle Jeunesse";"Prévention Vol";"Technoprévention"}))} -> 9 | J18: =I18/$I$24 -> 0.5625 | L18: Total | M18: =SUM(M15:M17) -> 161 | N18: =SUM(N15:N17) -> 1
D19: La Roue | E19: =COUNTIF('Liste usagers 2025'!$H$3:H878,"La Roue") -> 8 | F19: =E19/$E$21 -> 0.074074074 | H19: Services "Logement" | I19: {=SUM(COUNTIFS('Liste usagers 2025'!T$3:T$834, {"ULAC";"Syndicat des Locataires";"Foyer Anderlechtois";"Comensia"}))} -> 1 | J19: =I19/$I$24 -> 0.0625 | L19: Tranche d'âge
D20: Neerpede | E20: =COUNTIF('Liste usagers 2025'!$H$3:H879,"Neerpede") -> 3 | F20: =E20/$E$21 -> 0.027777778 | H20: Services Judiciaires | I20: {=SUM(COUNTIFS('Liste usagers 2025'!T$3:T$834, {"Justice de Paix";"Police";"Foyer Anderlechtois";"Service de Médiation à la Police"}))} -> 5 | J20: =I20/$I$24 -> 0.3125 | L20: < 18 ans | M20: =COUNTIF('Liste usagers 2025'!$E$3:E834,"Moins de 18 ans") -> 0 | N20: =IF($M$24=0, 0, M20/$M$24) -> 0
D21: Total | E21: =SUM(E13:E20) -> 108 | F21: =E21/$E$21 -> 1 | H21: Services communaux | I21: {=SUM(COUNTIFS('Liste usagers 2025'!T$3:T$834, {"CPAS";"Service Séniors";"Espaces Verts";"Service Mobilité";"Services de Médiation (autres communes)";"Antenne LISA (Vaillance)";"Antenne LISA (Peterbos)"}))} -> 0 | J21: =I21/$I$24 -> 0 | L21: 18 - 30 ans | M21: =COUNTIF('Liste usagers 2025'!$E$3:$E$834,"18 - 30 ans") -> 7 | N21: =IF($M$24=0, 0, M21/$M$24) -> 0.04964539
H22: Service du secteur associatif | I22: {=SUM(COUNTIFS('Liste usagers 2025'!T$3:T$834, {"PCS Albert";"Cactus";"Service Social de Cureghem";"CAW Westland";"Maison Médicale Horizon";"Maison Médicale Medikuregem"}))} -> 1 | J22: =I22/$I$24 -> 0.0625 | L22: 30 - 50 ans | M22: =COUNTIF('Liste usagers 2025'!$E$3:$E$834,"30 - 50 ans") -> 91 | N22: =IF($M$24=0, 0, M22/$M$24) -> 0.64539007
D23: Type de conflis traités | F23: Pourcentage | H23: Autres | I23: =COUNTIF('Liste usagers 2025'!R$3:R$834,"Autres") -> 0 | J23: =I23/$I$24 -> 0 | L23: 50 ans et + | M23: =COUNTIF('Liste usagers 2025'!$E$3:E834,"50 ans et +") -> 43 | N23: =IF($M$24=0, 0, M23/$M$24) -> 0.30496454
D24: Conflits de voisinage | E24: =COUNTIF('Liste usagers 2025'!P$3:P834,"Conflits de voisinage") -> 82 | F24: =E24/$E$6 -> 0.48235294 | H24: Total | I24: =SUM(I18:I23) -> 16 | J24: =I24/$I$24 -> 1 | L24: Total | M24: =SUM(M20:M23) -> 141 | N24: =SUM(N20:N23) -> 1
D25: Conflits riverains/Horeca | E25: =COUNTIF('Liste usagers 2025'!P$3:P834,"Conflits riverains/HORECA") -> 0 | F25: =E25/$E$6 -> 0 | H25: Orientation
D26: Conflits familiaux/conjugaux | E26: =COUNTIF('Liste usagers 2025'!P$3:P834,"Conflits familiaux/ Conjugaux") -> 16 | F26: =E26/$E$6 -> 0.094117647 | H26: Collègues Prévention | I26: {=SUM(COUNTIFS('Liste usagers 2025'!W$3:W$834, {"TSR";"CRIPA";"Gardiens de la Paix";"Pôle Assuétudes";"Pôle Jeunesse";"Prévention Vol";"Technoprévention"}))} -> 10 | J26: =I26/$E$6 -> 0.058823529
D27: Conflits locatifs | E27: =COUNTIF('Liste usagers 2025'!P$3:P834,"Conflits locatifs") -> 31 | F27: =E27/$E$6 -> 0.18235294 | H27: Services "Logement" | I27: {=SUM(COUNTIFS('Liste usagers 2025'!W$3:W$834, {"ULAC";"Syndicat des Locataires";"Foyer Anderlechtois";"Comensia"}))} -> 1 | J27: =I27/$E$6 -> 0.0058823529
D28: Copropriété | E28: =COUNTIF('Liste usagers 2025'!P$3:P834,"Copropriété") -> 12 | F28: =E28/$E$6 -> 0.070588235 | H28: Services Judiciaires | I28: {=SUM(COUNTIFS('Liste usagers 2025'!R$3:R$834, {"Justice de Paix";"Police";"Foyer Anderlechtois";"Service de Médiation à la Police"}))} -> 16 | J28: =I28/$E$6 -> 0.094117647
D29: Conflits en lien avec l'espace public | E29: =COUNTIF('Liste usagers 2025'!P$3:P834,"Conflits en lien avec l'espace public") -> 1 | F29: =E29/$E$6 -> 0.0058823529 | H29: Services communaux | I29: {=SUM(COUNTIFS('Liste usagers 2025'!W$3:W$834, {"CPAS";"Service Séniors";"Espaces Verts";"Service Mobilité";"Services de Médiation (autres communes)";"Antenne LISA (Vaillance)";"Antenne LISA (Peterbos)"}))} -> 0 | J29: =I29/$E$6 -> 0
D30: Cohabitation/Colocation | E30: =COUNTIF('Liste usagers 2025'!P$3:P834,"Cohabitation/Colocation") -> 1 | F30: =E30/$E$6 -> 0.0058823529 | H30: Service du secteur associatif | I30: {=SUM(COUNTIFS('Liste usagers 2025'!W$3:W$834, {"PCS Albert";"Cactus";"Service Social de Cureghem";"CAW Westland";"Maison Médicale Horizon";"Maison Médicale Medikuregem"}))} -> 1 | J30: =I30/$E$6 -> 0.0058823529
D31: Autres conflits | E31: =COUNTIF('Liste usagers 2025'!P$3:P834,"Autres conflits") -> 19 | F31: =E31/$E$6 -> 0.11176471 | H31: Autres | I31: =COUNTIF('Liste usagers 2025'!W$3:W834,"Autres") -> 1 | J31: =I31/$E$6 -> 0.0058823529
D32: Total | E32: =SUM(E24:E31) -> 162 | F32: =SUM(F24:F31) -> 0.95294118 | H32: Total | I32: =SUM(I26:I31) -> 29 | J32: =SUM(J26:J31) -> 0.17058824
H33: Issue de l'intervention
H34: Impossibilité technique (non-joignables) | I34: =COUNTIF('Liste usagers 2025'!Z$3:Z834,"Impossibilité technique (non-joignables)") -> 27 | J34: =I34/$I$41 -> 0.21259843
H35: Refus (de l'une ou des deux parties) | I35: =COUNTIF('Liste usagers 2025'!Z$3:Z834,"Refus (de l'une partie ou des deux)") -> 31 | J35: =I35/$I$41 -> 0.24409449
H36: Réorientation | I36: =COUNTIF('Liste usagers 2025'!Z$3:Z834,"Réorientation") -> 41 | J36: =I36/$I$41 -> 0.32283465
H37: Interruption du processus de médiation | I37: =COUNTIF('Liste usagers 2025'!Z$3:Z834,"Interruption du processus de médiation") -> 11 | J37: =I37/$I$41 -> 0.086614173
H38: Apaisement | I38: =COUNTIF('Liste usagers 2025'!Z$3:Z834,"Apaisement") -> 6 | J38: =I38/$I$41 -> 0.047244094
H39: Accord écrit | I39: =COUNTIF('Liste usagers 2025'!Z$3:Z834,"Accord écrit") -> 2 | J39: =I39/$I$41 -> 0.015748031
H40: Accord verbal | I40: =COUNTIF('Liste usagers 2025'!Z$3:Z834,"Accord verbal") -> 9 | J40: =I40/$I$41 -> 0.070866142
H41: Total | I41: =SUM(I34:I40) -> 127 | J41: =SUM(J34:J40) -> 1

Sheet Index
A1: Tranche d'âge | C1: ADRESSE | D1: SECTEUR
A2: Moins de 18 ans | C2: Rue Raymond van Der Bruggen CPAS | D2: Adresse de référence
A3: 18 - 30 ans | C3: Avenue Clemenceau | D3: Cureghem
A4: 30 - 50 ans | C4: Avenue Clémenceau | D4: Cureghem
A5: 50 ans et + | C5: Boulevard Poincaré | D5: Cureghem
C6: Chaussée de Mons 1-153/2-154 | D6: Cureghem
C7: Clos de la Petite Senne | D7: Cureghem
C8: Clos de l'Équerre | D8: Cureghem
C9: Place Alphonse Lemmens | D9: Cureghem
A10: Genre | C10: Place Bara | D10: Cureghem
A11: Homme | C11: Rue Abbé Cuylits | D11: Cureghem
A12: Femme | C12: Rue Bissé | D12: Cureghem
A13: Non binaire | C13: Rue Brogniez | D13: Cureghem
C14: Rue Broyère | D14: Cureghem
C15: Rue de la Bougie | D15: Cureghem
A16: Type de médiation | C16: Rue de la Clinique | D16: Cureghem
A17: Individuelle | C17: Rue de la Poterie | D17: Cureghem
A18: Collective | C18: Rue de la Rosée | D18: Cureghem
C19: Rue de l'Autonomie | D19: Cureghem
A20: Envoyeurs/Partenaires | C20: Rue de Liverpool | D20: Cureghem
A21: Antenne LISA (Peterbos) | C21: Rue des Matériaux | D21: Cureghem
A22: Antenne LISA (Vaillance) | C22: Rue des Mégissiers | D22: Cureghem
A23: Cactus | C23: Rue Docteur De Meersman | D23: Cureghem
A24: CAW Westland | C24: Rue du Chimiste | D24: Cureghem
A25: Comensia | C25: Rue du Compas | D25: Cureghem
A26: CPAS | C26: Rue Foppens | D26: Cureghem
A27: CRIPA | C27: Rue Gheude | D27: Cureghem
A28: Déjà venu | C28: Rue Haberman | D28: Cureghem
A29: Demande spontanée | C29: Rue Heyvaert | D29: Cureghem
A30: Espaces Verts | C30: Rue Jules Ruhl | D30: Cureghem
A31: Foyer Anderlechtois | C31: Rue Lambert Crickx | D31: Cureghem
... A50: Autre | C50: Place du Conseil | D50: Cureghem
C51: Place Grisar | D51: Cureghem
C52: Place Jorez | D52: Cureghem
C53: Rue Auguste Gevaert | D53: Cureghem
C54: Rue Bara | D54: Cureghem
C55: Rue Charles Parenté | D55: Cureghem
C56: Rue Chomé-Wyns | D56: Cureghem
C57: Rue de Fiennes | D57: Cureghem
C58: Rue de l'Ecole Moderne | D58: Cureghem
...
